2022-07-09 13:38:14,632 -  nornir.core -     INFO -        run() - Running task 'show_command_test' with args {} on 4 hosts
2022-07-09 13:38:14,860 - nornir.core.task -    ERROR -      start() - Host 'R3': task 'send_command' failed with traceback:
Traceback (most recent call last):
  File "/home/jcapps/nornir/.venv/lib/python3.10/site-packages/nornir/core/task.py", line 99, in start
    r = self.task(self, **self.params)
  File "/home/jcapps/nornir/.venv/lib/python3.10/site-packages/nornir_scrapli/tasks/core/send_command.py", line 36, in send_command
    scrapli_conn = task.host.get_connection("scrapli", task.nornir.config)
  File "/home/jcapps/nornir/.venv/lib/python3.10/site-packages/nornir/core/inventory.py", line 494, in get_connection
    self.open_connection(
  File "/home/jcapps/nornir/.venv/lib/python3.10/site-packages/nornir/core/inventory.py", line 546, in open_connection
    conn_obj.open(
  File "/home/jcapps/nornir/.venv/lib/python3.10/site-packages/nornir_scrapli/connection.py", line 98, in open
    connection.open()
  File "/home/jcapps/nornir/.venv/lib/python3.10/site-packages/scrapli/driver/base/sync_driver.py", line 86, in open
    self.channel.channel_authenticate_ssh(
  File "/home/jcapps/nornir/.venv/lib/python3.10/site-packages/scrapli/decorators.py", line 280, in decorate
    return self._multiprocessing_timeout(
  File "/home/jcapps/nornir/.venv/lib/python3.10/site-packages/scrapli/decorators.py", line 341, in _multiprocessing_timeout
    return future.result()
  File "/usr/lib/python3.10/concurrent/futures/_base.py", line 439, in result
    return self.__get_result()
  File "/usr/lib/python3.10/concurrent/futures/_base.py", line 391, in __get_result
    raise self._exception
  File "/usr/lib/python3.10/concurrent/futures/thread.py", line 58, in run
    result = self.fn(*self.args, **self.kwargs)
  File "/home/jcapps/nornir/.venv/lib/python3.10/site-packages/scrapli/channel/sync_channel.py", line 290, in channel_authenticate_ssh
    self._ssh_message_handler(output=authenticate_buf)
  File "/home/jcapps/nornir/.venv/lib/python3.10/site-packages/scrapli/channel/base_channel.py", line 432, in _ssh_message_handler
    raise ScrapliAuthenticationFailed(msg)
scrapli.exceptions.ScrapliAuthenticationFailed: Host key verification failed

2022-07-09 13:38:14,860 - nornir.core.task -    ERROR -      start() - Host 'R3': task 'show_command_test' failed with traceback:
Traceback (most recent call last):
  File "/home/jcapps/nornir/.venv/lib/python3.10/site-packages/nornir/core/task.py", line 99, in start
    r = self.task(self, **self.params)
  File "/home/jcapps/nornir/runbook2.py", line 8, in show_command_test
    task.run(task=send_command, command="show ip interface brief")
  File "/home/jcapps/nornir/.venv/lib/python3.10/site-packages/nornir/core/task.py", line 174, in run
    raise NornirSubTaskError(task=run_task, result=r)
nornir.core.exceptions.NornirSubTaskError: Subtask: send_command (failed)


2022-07-09 13:38:14,962 - nornir.core.task -    ERROR -      start() - Host 'R1': task 'send_command' failed with traceback:
Traceback (most recent call last):
  File "/home/jcapps/nornir/.venv/lib/python3.10/site-packages/nornir/core/task.py", line 99, in start
    r = self.task(self, **self.params)
  File "/home/jcapps/nornir/.venv/lib/python3.10/site-packages/nornir_scrapli/tasks/core/send_command.py", line 36, in send_command
    scrapli_conn = task.host.get_connection("scrapli", task.nornir.config)
  File "/home/jcapps/nornir/.venv/lib/python3.10/site-packages/nornir/core/inventory.py", line 494, in get_connection
    self.open_connection(
  File "/home/jcapps/nornir/.venv/lib/python3.10/site-packages/nornir/core/inventory.py", line 546, in open_connection
    conn_obj.open(
  File "/home/jcapps/nornir/.venv/lib/python3.10/site-packages/nornir_scrapli/connection.py", line 98, in open
    connection.open()
  File "/home/jcapps/nornir/.venv/lib/python3.10/site-packages/scrapli/driver/base/sync_driver.py", line 86, in open
    self.channel.channel_authenticate_ssh(
  File "/home/jcapps/nornir/.venv/lib/python3.10/site-packages/scrapli/decorators.py", line 280, in decorate
    return self._multiprocessing_timeout(
  File "/home/jcapps/nornir/.venv/lib/python3.10/site-packages/scrapli/decorators.py", line 341, in _multiprocessing_timeout
    return future.result()
  File "/usr/lib/python3.10/concurrent/futures/_base.py", line 439, in result
    return self.__get_result()
  File "/usr/lib/python3.10/concurrent/futures/_base.py", line 391, in __get_result
    raise self._exception
  File "/usr/lib/python3.10/concurrent/futures/thread.py", line 58, in run
    result = self.fn(*self.args, **self.kwargs)
  File "/home/jcapps/nornir/.venv/lib/python3.10/site-packages/scrapli/channel/sync_channel.py", line 290, in channel_authenticate_ssh
    self._ssh_message_handler(output=authenticate_buf)
  File "/home/jcapps/nornir/.venv/lib/python3.10/site-packages/scrapli/channel/base_channel.py", line 432, in _ssh_message_handler
    raise ScrapliAuthenticationFailed(msg)
scrapli.exceptions.ScrapliAuthenticationFailed: Host key verification failed

2022-07-09 13:38:14,962 - nornir.core.task -    ERROR -      start() - Host 'R1': task 'show_command_test' failed with traceback:
Traceback (most recent call last):
  File "/home/jcapps/nornir/.venv/lib/python3.10/site-packages/nornir/core/task.py", line 99, in start
    r = self.task(self, **self.params)
  File "/home/jcapps/nornir/runbook2.py", line 8, in show_command_test
    task.run(task=send_command, command="show ip interface brief")
  File "/home/jcapps/nornir/.venv/lib/python3.10/site-packages/nornir/core/task.py", line 174, in run
    raise NornirSubTaskError(task=run_task, result=r)
nornir.core.exceptions.NornirSubTaskError: Subtask: send_command (failed)


2022-07-09 13:40:42,809 -  nornir.core -     INFO -        run() - Running task 'show_command_test' with args {} on 4 hosts
2022-07-09 13:40:42,955 - nornir.core.task -    ERROR -      start() - Host 'R1': task 'send_command' failed with traceback:
Traceback (most recent call last):
  File "/home/jcapps/nornir/.venv/lib/python3.10/site-packages/nornir/core/task.py", line 99, in start
    r = self.task(self, **self.params)
  File "/home/jcapps/nornir/.venv/lib/python3.10/site-packages/nornir_scrapli/tasks/core/send_command.py", line 36, in send_command
    scrapli_conn = task.host.get_connection("scrapli", task.nornir.config)
  File "/home/jcapps/nornir/.venv/lib/python3.10/site-packages/nornir/core/inventory.py", line 494, in get_connection
    self.open_connection(
  File "/home/jcapps/nornir/.venv/lib/python3.10/site-packages/nornir/core/inventory.py", line 546, in open_connection
    conn_obj.open(
  File "/home/jcapps/nornir/.venv/lib/python3.10/site-packages/nornir_scrapli/connection.py", line 98, in open
    connection.open()
  File "/home/jcapps/nornir/.venv/lib/python3.10/site-packages/scrapli/driver/base/sync_driver.py", line 86, in open
    self.channel.channel_authenticate_ssh(
  File "/home/jcapps/nornir/.venv/lib/python3.10/site-packages/scrapli/decorators.py", line 280, in decorate
    return self._multiprocessing_timeout(
  File "/home/jcapps/nornir/.venv/lib/python3.10/site-packages/scrapli/decorators.py", line 341, in _multiprocessing_timeout
    return future.result()
  File "/usr/lib/python3.10/concurrent/futures/_base.py", line 439, in result
    return self.__get_result()
  File "/usr/lib/python3.10/concurrent/futures/_base.py", line 391, in __get_result
    raise self._exception
  File "/usr/lib/python3.10/concurrent/futures/thread.py", line 58, in run
    result = self.fn(*self.args, **self.kwargs)
  File "/home/jcapps/nornir/.venv/lib/python3.10/site-packages/scrapli/channel/sync_channel.py", line 290, in channel_authenticate_ssh
    self._ssh_message_handler(output=authenticate_buf)
  File "/home/jcapps/nornir/.venv/lib/python3.10/site-packages/scrapli/channel/base_channel.py", line 432, in _ssh_message_handler
    raise ScrapliAuthenticationFailed(msg)
scrapli.exceptions.ScrapliAuthenticationFailed: Host key verification failed

2022-07-09 13:40:42,955 - nornir.core.task -    ERROR -      start() - Host 'R1': task 'show_command_test' failed with traceback:
Traceback (most recent call last):
  File "/home/jcapps/nornir/.venv/lib/python3.10/site-packages/nornir/core/task.py", line 99, in start
    r = self.task(self, **self.params)
  File "/home/jcapps/nornir/runbook2.py", line 8, in show_command_test
    task.run(task=send_command, command="show ip interface brief")
  File "/home/jcapps/nornir/.venv/lib/python3.10/site-packages/nornir/core/task.py", line 174, in run
    raise NornirSubTaskError(task=run_task, result=r)
nornir.core.exceptions.NornirSubTaskError: Subtask: send_command (failed)


2022-07-09 13:40:43,161 - nornir.core.task -    ERROR -      start() - Host 'R3': task 'send_command' failed with traceback:
Traceback (most recent call last):
  File "/home/jcapps/nornir/.venv/lib/python3.10/site-packages/nornir/core/task.py", line 99, in start
    r = self.task(self, **self.params)
  File "/home/jcapps/nornir/.venv/lib/python3.10/site-packages/nornir_scrapli/tasks/core/send_command.py", line 36, in send_command
    scrapli_conn = task.host.get_connection("scrapli", task.nornir.config)
  File "/home/jcapps/nornir/.venv/lib/python3.10/site-packages/nornir/core/inventory.py", line 494, in get_connection
    self.open_connection(
  File "/home/jcapps/nornir/.venv/lib/python3.10/site-packages/nornir/core/inventory.py", line 546, in open_connection
    conn_obj.open(
  File "/home/jcapps/nornir/.venv/lib/python3.10/site-packages/nornir_scrapli/connection.py", line 98, in open
    connection.open()
  File "/home/jcapps/nornir/.venv/lib/python3.10/site-packages/scrapli/driver/base/sync_driver.py", line 86, in open
    self.channel.channel_authenticate_ssh(
  File "/home/jcapps/nornir/.venv/lib/python3.10/site-packages/scrapli/decorators.py", line 280, in decorate
    return self._multiprocessing_timeout(
  File "/home/jcapps/nornir/.venv/lib/python3.10/site-packages/scrapli/decorators.py", line 341, in _multiprocessing_timeout
    return future.result()
  File "/usr/lib/python3.10/concurrent/futures/_base.py", line 439, in result
    return self.__get_result()
  File "/usr/lib/python3.10/concurrent/futures/_base.py", line 391, in __get_result
    raise self._exception
  File "/usr/lib/python3.10/concurrent/futures/thread.py", line 58, in run
    result = self.fn(*self.args, **self.kwargs)
  File "/home/jcapps/nornir/.venv/lib/python3.10/site-packages/scrapli/channel/sync_channel.py", line 290, in channel_authenticate_ssh
    self._ssh_message_handler(output=authenticate_buf)
  File "/home/jcapps/nornir/.venv/lib/python3.10/site-packages/scrapli/channel/base_channel.py", line 432, in _ssh_message_handler
    raise ScrapliAuthenticationFailed(msg)
scrapli.exceptions.ScrapliAuthenticationFailed: Host key verification failed

2022-07-09 13:40:43,161 - nornir.core.task -    ERROR -      start() - Host 'R3': task 'show_command_test' failed with traceback:
Traceback (most recent call last):
  File "/home/jcapps/nornir/.venv/lib/python3.10/site-packages/nornir/core/task.py", line 99, in start
    r = self.task(self, **self.params)
  File "/home/jcapps/nornir/runbook2.py", line 8, in show_command_test
    task.run(task=send_command, command="show ip interface brief")
  File "/home/jcapps/nornir/.venv/lib/python3.10/site-packages/nornir/core/task.py", line 174, in run
    raise NornirSubTaskError(task=run_task, result=r)
nornir.core.exceptions.NornirSubTaskError: Subtask: send_command (failed)


2022-07-09 13:41:14,237 -  nornir.core -     INFO -        run() - Running task 'show_command_test' with args {} on 4 hosts
2022-07-09 13:41:14,579 - nornir.core.task -    ERROR -      start() - Host 'R1': task 'send_command' failed with traceback:
Traceback (most recent call last):
  File "/home/jcapps/nornir/.venv/lib/python3.10/site-packages/nornir/core/task.py", line 99, in start
    r = self.task(self, **self.params)
  File "/home/jcapps/nornir/.venv/lib/python3.10/site-packages/nornir_scrapli/tasks/core/send_command.py", line 36, in send_command
    scrapli_conn = task.host.get_connection("scrapli", task.nornir.config)
  File "/home/jcapps/nornir/.venv/lib/python3.10/site-packages/nornir/core/inventory.py", line 494, in get_connection
    self.open_connection(
  File "/home/jcapps/nornir/.venv/lib/python3.10/site-packages/nornir/core/inventory.py", line 546, in open_connection
    conn_obj.open(
  File "/home/jcapps/nornir/.venv/lib/python3.10/site-packages/nornir_scrapli/connection.py", line 98, in open
    connection.open()
  File "/home/jcapps/nornir/.venv/lib/python3.10/site-packages/scrapli/driver/base/sync_driver.py", line 86, in open
    self.channel.channel_authenticate_ssh(
  File "/home/jcapps/nornir/.venv/lib/python3.10/site-packages/scrapli/decorators.py", line 280, in decorate
    return self._multiprocessing_timeout(
  File "/home/jcapps/nornir/.venv/lib/python3.10/site-packages/scrapli/decorators.py", line 341, in _multiprocessing_timeout
    return future.result()
  File "/usr/lib/python3.10/concurrent/futures/_base.py", line 439, in result
    return self.__get_result()
  File "/usr/lib/python3.10/concurrent/futures/_base.py", line 391, in __get_result
    raise self._exception
  File "/usr/lib/python3.10/concurrent/futures/thread.py", line 58, in run
    result = self.fn(*self.args, **self.kwargs)
  File "/home/jcapps/nornir/.venv/lib/python3.10/site-packages/scrapli/channel/sync_channel.py", line 290, in channel_authenticate_ssh
    self._ssh_message_handler(output=authenticate_buf)
  File "/home/jcapps/nornir/.venv/lib/python3.10/site-packages/scrapli/channel/base_channel.py", line 432, in _ssh_message_handler
    raise ScrapliAuthenticationFailed(msg)
scrapli.exceptions.ScrapliAuthenticationFailed: Host key verification failed

2022-07-09 13:41:14,580 - nornir.core.task -    ERROR -      start() - Host 'R1': task 'show_command_test' failed with traceback:
Traceback (most recent call last):
  File "/home/jcapps/nornir/.venv/lib/python3.10/site-packages/nornir/core/task.py", line 99, in start
    r = self.task(self, **self.params)
  File "/home/jcapps/nornir/runbook2.py", line 8, in show_command_test
    task.run(task=send_command, command="show ip interface brief")
  File "/home/jcapps/nornir/.venv/lib/python3.10/site-packages/nornir/core/task.py", line 174, in run
    raise NornirSubTaskError(task=run_task, result=r)
nornir.core.exceptions.NornirSubTaskError: Subtask: send_command (failed)


2022-07-09 13:41:14,587 - nornir.core.task -    ERROR -      start() - Host 'R3': task 'send_command' failed with traceback:
Traceback (most recent call last):
  File "/home/jcapps/nornir/.venv/lib/python3.10/site-packages/nornir/core/task.py", line 99, in start
    r = self.task(self, **self.params)
  File "/home/jcapps/nornir/.venv/lib/python3.10/site-packages/nornir_scrapli/tasks/core/send_command.py", line 36, in send_command
    scrapli_conn = task.host.get_connection("scrapli", task.nornir.config)
  File "/home/jcapps/nornir/.venv/lib/python3.10/site-packages/nornir/core/inventory.py", line 494, in get_connection
    self.open_connection(
  File "/home/jcapps/nornir/.venv/lib/python3.10/site-packages/nornir/core/inventory.py", line 546, in open_connection
    conn_obj.open(
  File "/home/jcapps/nornir/.venv/lib/python3.10/site-packages/nornir_scrapli/connection.py", line 98, in open
    connection.open()
  File "/home/jcapps/nornir/.venv/lib/python3.10/site-packages/scrapli/driver/base/sync_driver.py", line 86, in open
    self.channel.channel_authenticate_ssh(
  File "/home/jcapps/nornir/.venv/lib/python3.10/site-packages/scrapli/decorators.py", line 280, in decorate
    return self._multiprocessing_timeout(
  File "/home/jcapps/nornir/.venv/lib/python3.10/site-packages/scrapli/decorators.py", line 341, in _multiprocessing_timeout
    return future.result()
  File "/usr/lib/python3.10/concurrent/futures/_base.py", line 439, in result
    return self.__get_result()
  File "/usr/lib/python3.10/concurrent/futures/_base.py", line 391, in __get_result
    raise self._exception
  File "/usr/lib/python3.10/concurrent/futures/thread.py", line 58, in run
    result = self.fn(*self.args, **self.kwargs)
  File "/home/jcapps/nornir/.venv/lib/python3.10/site-packages/scrapli/channel/sync_channel.py", line 290, in channel_authenticate_ssh
    self._ssh_message_handler(output=authenticate_buf)
  File "/home/jcapps/nornir/.venv/lib/python3.10/site-packages/scrapli/channel/base_channel.py", line 432, in _ssh_message_handler
    raise ScrapliAuthenticationFailed(msg)
scrapli.exceptions.ScrapliAuthenticationFailed: Host key verification failed

2022-07-09 13:41:14,588 - nornir.core.task -    ERROR -      start() - Host 'R3': task 'show_command_test' failed with traceback:
Traceback (most recent call last):
  File "/home/jcapps/nornir/.venv/lib/python3.10/site-packages/nornir/core/task.py", line 99, in start
    r = self.task(self, **self.params)
  File "/home/jcapps/nornir/runbook2.py", line 8, in show_command_test
    task.run(task=send_command, command="show ip interface brief")
  File "/home/jcapps/nornir/.venv/lib/python3.10/site-packages/nornir/core/task.py", line 174, in run
    raise NornirSubTaskError(task=run_task, result=r)
nornir.core.exceptions.NornirSubTaskError: Subtask: send_command (failed)


2022-07-09 13:41:28,215 -  nornir.core -     INFO -        run() - Running task 'show_command_test' with args {} on 4 hosts
2022-07-09 13:41:28,357 - nornir.core.task -    ERROR -      start() - Host 'R1': task 'send_command' failed with traceback:
Traceback (most recent call last):
  File "/home/jcapps/nornir/.venv/lib/python3.10/site-packages/nornir/core/task.py", line 99, in start
    r = self.task(self, **self.params)
  File "/home/jcapps/nornir/.venv/lib/python3.10/site-packages/nornir_scrapli/tasks/core/send_command.py", line 36, in send_command
    scrapli_conn = task.host.get_connection("scrapli", task.nornir.config)
  File "/home/jcapps/nornir/.venv/lib/python3.10/site-packages/nornir/core/inventory.py", line 494, in get_connection
    self.open_connection(
  File "/home/jcapps/nornir/.venv/lib/python3.10/site-packages/nornir/core/inventory.py", line 546, in open_connection
    conn_obj.open(
  File "/home/jcapps/nornir/.venv/lib/python3.10/site-packages/nornir_scrapli/connection.py", line 98, in open
    connection.open()
  File "/home/jcapps/nornir/.venv/lib/python3.10/site-packages/scrapli/driver/base/sync_driver.py", line 86, in open
    self.channel.channel_authenticate_ssh(
  File "/home/jcapps/nornir/.venv/lib/python3.10/site-packages/scrapli/decorators.py", line 280, in decorate
    return self._multiprocessing_timeout(
  File "/home/jcapps/nornir/.venv/lib/python3.10/site-packages/scrapli/decorators.py", line 341, in _multiprocessing_timeout
    return future.result()
  File "/usr/lib/python3.10/concurrent/futures/_base.py", line 439, in result
    return self.__get_result()
  File "/usr/lib/python3.10/concurrent/futures/_base.py", line 391, in __get_result
    raise self._exception
  File "/usr/lib/python3.10/concurrent/futures/thread.py", line 58, in run
    result = self.fn(*self.args, **self.kwargs)
  File "/home/jcapps/nornir/.venv/lib/python3.10/site-packages/scrapli/channel/sync_channel.py", line 290, in channel_authenticate_ssh
    self._ssh_message_handler(output=authenticate_buf)
  File "/home/jcapps/nornir/.venv/lib/python3.10/site-packages/scrapli/channel/base_channel.py", line 432, in _ssh_message_handler
    raise ScrapliAuthenticationFailed(msg)
scrapli.exceptions.ScrapliAuthenticationFailed: Host key verification failed

2022-07-09 13:41:28,358 - nornir.core.task -    ERROR -      start() - Host 'R1': task 'show_command_test' failed with traceback:
Traceback (most recent call last):
  File "/home/jcapps/nornir/.venv/lib/python3.10/site-packages/nornir/core/task.py", line 99, in start
    r = self.task(self, **self.params)
  File "/home/jcapps/nornir/runbook2.py", line 8, in show_command_test
    task.run(task=send_command, command="show ip interface brief")
  File "/home/jcapps/nornir/.venv/lib/python3.10/site-packages/nornir/core/task.py", line 174, in run
    raise NornirSubTaskError(task=run_task, result=r)
nornir.core.exceptions.NornirSubTaskError: Subtask: send_command (failed)


2022-07-09 13:41:28,372 - nornir.core.task -    ERROR -      start() - Host 'R3': task 'send_command' failed with traceback:
Traceback (most recent call last):
  File "/home/jcapps/nornir/.venv/lib/python3.10/site-packages/nornir/core/task.py", line 99, in start
    r = self.task(self, **self.params)
  File "/home/jcapps/nornir/.venv/lib/python3.10/site-packages/nornir_scrapli/tasks/core/send_command.py", line 36, in send_command
    scrapli_conn = task.host.get_connection("scrapli", task.nornir.config)
  File "/home/jcapps/nornir/.venv/lib/python3.10/site-packages/nornir/core/inventory.py", line 494, in get_connection
    self.open_connection(
  File "/home/jcapps/nornir/.venv/lib/python3.10/site-packages/nornir/core/inventory.py", line 546, in open_connection
    conn_obj.open(
  File "/home/jcapps/nornir/.venv/lib/python3.10/site-packages/nornir_scrapli/connection.py", line 98, in open
    connection.open()
  File "/home/jcapps/nornir/.venv/lib/python3.10/site-packages/scrapli/driver/base/sync_driver.py", line 86, in open
    self.channel.channel_authenticate_ssh(
  File "/home/jcapps/nornir/.venv/lib/python3.10/site-packages/scrapli/decorators.py", line 280, in decorate
    return self._multiprocessing_timeout(
  File "/home/jcapps/nornir/.venv/lib/python3.10/site-packages/scrapli/decorators.py", line 341, in _multiprocessing_timeout
    return future.result()
  File "/usr/lib/python3.10/concurrent/futures/_base.py", line 439, in result
    return self.__get_result()
  File "/usr/lib/python3.10/concurrent/futures/_base.py", line 391, in __get_result
    raise self._exception
  File "/usr/lib/python3.10/concurrent/futures/thread.py", line 58, in run
    result = self.fn(*self.args, **self.kwargs)
  File "/home/jcapps/nornir/.venv/lib/python3.10/site-packages/scrapli/channel/sync_channel.py", line 290, in channel_authenticate_ssh
    self._ssh_message_handler(output=authenticate_buf)
  File "/home/jcapps/nornir/.venv/lib/python3.10/site-packages/scrapli/channel/base_channel.py", line 432, in _ssh_message_handler
    raise ScrapliAuthenticationFailed(msg)
scrapli.exceptions.ScrapliAuthenticationFailed: Host key verification failed

2022-07-09 13:41:28,372 - nornir.core.task -    ERROR -      start() - Host 'R3': task 'show_command_test' failed with traceback:
Traceback (most recent call last):
  File "/home/jcapps/nornir/.venv/lib/python3.10/site-packages/nornir/core/task.py", line 99, in start
    r = self.task(self, **self.params)
  File "/home/jcapps/nornir/runbook2.py", line 8, in show_command_test
    task.run(task=send_command, command="show ip interface brief")
  File "/home/jcapps/nornir/.venv/lib/python3.10/site-packages/nornir/core/task.py", line 174, in run
    raise NornirSubTaskError(task=run_task, result=r)
nornir.core.exceptions.NornirSubTaskError: Subtask: send_command (failed)


2022-07-09 13:44:52,291 -  nornir.core -     INFO -        run() - Running task 'show_command_test' with args {} on 4 hosts
2022-07-09 13:44:52,447 - nornir.core.task -    ERROR -      start() - Host 'R2': task 'send_command' failed with traceback:
Traceback (most recent call last):
  File "/home/jcapps/nornir/.venv/lib/python3.10/site-packages/nornir/core/task.py", line 99, in start
    r = self.task(self, **self.params)
  File "/home/jcapps/nornir/.venv/lib/python3.10/site-packages/nornir_scrapli/tasks/core/send_command.py", line 36, in send_command
    scrapli_conn = task.host.get_connection("scrapli", task.nornir.config)
  File "/home/jcapps/nornir/.venv/lib/python3.10/site-packages/nornir/core/inventory.py", line 494, in get_connection
    self.open_connection(
  File "/home/jcapps/nornir/.venv/lib/python3.10/site-packages/nornir/core/inventory.py", line 546, in open_connection
    conn_obj.open(
  File "/home/jcapps/nornir/.venv/lib/python3.10/site-packages/nornir_scrapli/connection.py", line 98, in open
    connection.open()
  File "/home/jcapps/nornir/.venv/lib/python3.10/site-packages/scrapli/driver/base/sync_driver.py", line 86, in open
    self.channel.channel_authenticate_ssh(
  File "/home/jcapps/nornir/.venv/lib/python3.10/site-packages/scrapli/decorators.py", line 280, in decorate
    return self._multiprocessing_timeout(
  File "/home/jcapps/nornir/.venv/lib/python3.10/site-packages/scrapli/decorators.py", line 341, in _multiprocessing_timeout
    return future.result()
  File "/usr/lib/python3.10/concurrent/futures/_base.py", line 439, in result
    return self.__get_result()
  File "/usr/lib/python3.10/concurrent/futures/_base.py", line 391, in __get_result
    raise self._exception
  File "/usr/lib/python3.10/concurrent/futures/thread.py", line 58, in run
    result = self.fn(*self.args, **self.kwargs)
  File "/home/jcapps/nornir/.venv/lib/python3.10/site-packages/scrapli/channel/sync_channel.py", line 290, in channel_authenticate_ssh
    self._ssh_message_handler(output=authenticate_buf)
  File "/home/jcapps/nornir/.venv/lib/python3.10/site-packages/scrapli/channel/base_channel.py", line 432, in _ssh_message_handler
    raise ScrapliAuthenticationFailed(msg)
scrapli.exceptions.ScrapliAuthenticationFailed: Host key verification failed

2022-07-09 13:44:52,448 - nornir.core.task -    ERROR -      start() - Host 'R4': task 'send_command' failed with traceback:
Traceback (most recent call last):
  File "/home/jcapps/nornir/.venv/lib/python3.10/site-packages/nornir/core/task.py", line 99, in start
    r = self.task(self, **self.params)
  File "/home/jcapps/nornir/.venv/lib/python3.10/site-packages/nornir_scrapli/tasks/core/send_command.py", line 36, in send_command
    scrapli_conn = task.host.get_connection("scrapli", task.nornir.config)
  File "/home/jcapps/nornir/.venv/lib/python3.10/site-packages/nornir/core/inventory.py", line 494, in get_connection
    self.open_connection(
  File "/home/jcapps/nornir/.venv/lib/python3.10/site-packages/nornir/core/inventory.py", line 546, in open_connection
    conn_obj.open(
  File "/home/jcapps/nornir/.venv/lib/python3.10/site-packages/nornir_scrapli/connection.py", line 98, in open
    connection.open()
  File "/home/jcapps/nornir/.venv/lib/python3.10/site-packages/scrapli/driver/base/sync_driver.py", line 86, in open
    self.channel.channel_authenticate_ssh(
  File "/home/jcapps/nornir/.venv/lib/python3.10/site-packages/scrapli/decorators.py", line 280, in decorate
    return self._multiprocessing_timeout(
  File "/home/jcapps/nornir/.venv/lib/python3.10/site-packages/scrapli/decorators.py", line 341, in _multiprocessing_timeout
    return future.result()
  File "/usr/lib/python3.10/concurrent/futures/_base.py", line 439, in result
    return self.__get_result()
  File "/usr/lib/python3.10/concurrent/futures/_base.py", line 391, in __get_result
    raise self._exception
  File "/usr/lib/python3.10/concurrent/futures/thread.py", line 58, in run
    result = self.fn(*self.args, **self.kwargs)
  File "/home/jcapps/nornir/.venv/lib/python3.10/site-packages/scrapli/channel/sync_channel.py", line 290, in channel_authenticate_ssh
    self._ssh_message_handler(output=authenticate_buf)
  File "/home/jcapps/nornir/.venv/lib/python3.10/site-packages/scrapli/channel/base_channel.py", line 432, in _ssh_message_handler
    raise ScrapliAuthenticationFailed(msg)
scrapli.exceptions.ScrapliAuthenticationFailed: Host key verification failed

2022-07-09 13:44:52,448 - nornir.core.task -    ERROR -      start() - Host 'R2': task 'show_command_test' failed with traceback:
Traceback (most recent call last):
  File "/home/jcapps/nornir/.venv/lib/python3.10/site-packages/nornir/core/task.py", line 99, in start
    r = self.task(self, **self.params)
  File "/home/jcapps/nornir/runbook2.py", line 8, in show_command_test
    task.run(task=send_command, command="show ip interface brief")
  File "/home/jcapps/nornir/.venv/lib/python3.10/site-packages/nornir/core/task.py", line 174, in run
    raise NornirSubTaskError(task=run_task, result=r)
nornir.core.exceptions.NornirSubTaskError: Subtask: send_command (failed)


2022-07-09 13:44:52,448 - nornir.core.task -    ERROR -      start() - Host 'R4': task 'show_command_test' failed with traceback:
Traceback (most recent call last):
  File "/home/jcapps/nornir/.venv/lib/python3.10/site-packages/nornir/core/task.py", line 99, in start
    r = self.task(self, **self.params)
  File "/home/jcapps/nornir/runbook2.py", line 8, in show_command_test
    task.run(task=send_command, command="show ip interface brief")
  File "/home/jcapps/nornir/.venv/lib/python3.10/site-packages/nornir/core/task.py", line 174, in run
    raise NornirSubTaskError(task=run_task, result=r)
nornir.core.exceptions.NornirSubTaskError: Subtask: send_command (failed)


2022-07-09 13:44:52,685 - nornir.core.task -    ERROR -      start() - Host 'R3': task 'send_command' failed with traceback:
Traceback (most recent call last):
  File "/home/jcapps/nornir/.venv/lib/python3.10/site-packages/nornir/core/task.py", line 99, in start
    r = self.task(self, **self.params)
  File "/home/jcapps/nornir/.venv/lib/python3.10/site-packages/nornir_scrapli/tasks/core/send_command.py", line 36, in send_command
    scrapli_conn = task.host.get_connection("scrapli", task.nornir.config)
  File "/home/jcapps/nornir/.venv/lib/python3.10/site-packages/nornir/core/inventory.py", line 494, in get_connection
    self.open_connection(
  File "/home/jcapps/nornir/.venv/lib/python3.10/site-packages/nornir/core/inventory.py", line 546, in open_connection
    conn_obj.open(
  File "/home/jcapps/nornir/.venv/lib/python3.10/site-packages/nornir_scrapli/connection.py", line 98, in open
    connection.open()
  File "/home/jcapps/nornir/.venv/lib/python3.10/site-packages/scrapli/driver/base/sync_driver.py", line 86, in open
    self.channel.channel_authenticate_ssh(
  File "/home/jcapps/nornir/.venv/lib/python3.10/site-packages/scrapli/decorators.py", line 280, in decorate
    return self._multiprocessing_timeout(
  File "/home/jcapps/nornir/.venv/lib/python3.10/site-packages/scrapli/decorators.py", line 341, in _multiprocessing_timeout
    return future.result()
  File "/usr/lib/python3.10/concurrent/futures/_base.py", line 439, in result
    return self.__get_result()
  File "/usr/lib/python3.10/concurrent/futures/_base.py", line 391, in __get_result
    raise self._exception
  File "/usr/lib/python3.10/concurrent/futures/thread.py", line 58, in run
    result = self.fn(*self.args, **self.kwargs)
  File "/home/jcapps/nornir/.venv/lib/python3.10/site-packages/scrapli/channel/sync_channel.py", line 290, in channel_authenticate_ssh
    self._ssh_message_handler(output=authenticate_buf)
  File "/home/jcapps/nornir/.venv/lib/python3.10/site-packages/scrapli/channel/base_channel.py", line 432, in _ssh_message_handler
    raise ScrapliAuthenticationFailed(msg)
scrapli.exceptions.ScrapliAuthenticationFailed: Host key verification failed

2022-07-09 13:44:52,686 - nornir.core.task -    ERROR -      start() - Host 'R3': task 'show_command_test' failed with traceback:
Traceback (most recent call last):
  File "/home/jcapps/nornir/.venv/lib/python3.10/site-packages/nornir/core/task.py", line 99, in start
    r = self.task(self, **self.params)
  File "/home/jcapps/nornir/runbook2.py", line 8, in show_command_test
    task.run(task=send_command, command="show ip interface brief")
  File "/home/jcapps/nornir/.venv/lib/python3.10/site-packages/nornir/core/task.py", line 174, in run
    raise NornirSubTaskError(task=run_task, result=r)
nornir.core.exceptions.NornirSubTaskError: Subtask: send_command (failed)


2022-07-09 13:44:52,692 - nornir.core.task -    ERROR -      start() - Host 'R1': task 'send_command' failed with traceback:
Traceback (most recent call last):
  File "/home/jcapps/nornir/.venv/lib/python3.10/site-packages/nornir/core/task.py", line 99, in start
    r = self.task(self, **self.params)
  File "/home/jcapps/nornir/.venv/lib/python3.10/site-packages/nornir_scrapli/tasks/core/send_command.py", line 36, in send_command
    scrapli_conn = task.host.get_connection("scrapli", task.nornir.config)
  File "/home/jcapps/nornir/.venv/lib/python3.10/site-packages/nornir/core/inventory.py", line 494, in get_connection
    self.open_connection(
  File "/home/jcapps/nornir/.venv/lib/python3.10/site-packages/nornir/core/inventory.py", line 546, in open_connection
    conn_obj.open(
  File "/home/jcapps/nornir/.venv/lib/python3.10/site-packages/nornir_scrapli/connection.py", line 98, in open
    connection.open()
  File "/home/jcapps/nornir/.venv/lib/python3.10/site-packages/scrapli/driver/base/sync_driver.py", line 86, in open
    self.channel.channel_authenticate_ssh(
  File "/home/jcapps/nornir/.venv/lib/python3.10/site-packages/scrapli/decorators.py", line 280, in decorate
    return self._multiprocessing_timeout(
  File "/home/jcapps/nornir/.venv/lib/python3.10/site-packages/scrapli/decorators.py", line 341, in _multiprocessing_timeout
    return future.result()
  File "/usr/lib/python3.10/concurrent/futures/_base.py", line 439, in result
    return self.__get_result()
  File "/usr/lib/python3.10/concurrent/futures/_base.py", line 391, in __get_result
    raise self._exception
  File "/usr/lib/python3.10/concurrent/futures/thread.py", line 58, in run
    result = self.fn(*self.args, **self.kwargs)
  File "/home/jcapps/nornir/.venv/lib/python3.10/site-packages/scrapli/channel/sync_channel.py", line 290, in channel_authenticate_ssh
    self._ssh_message_handler(output=authenticate_buf)
  File "/home/jcapps/nornir/.venv/lib/python3.10/site-packages/scrapli/channel/base_channel.py", line 432, in _ssh_message_handler
    raise ScrapliAuthenticationFailed(msg)
scrapli.exceptions.ScrapliAuthenticationFailed: Host key verification failed

2022-07-09 13:44:52,693 - nornir.core.task -    ERROR -      start() - Host 'R1': task 'show_command_test' failed with traceback:
Traceback (most recent call last):
  File "/home/jcapps/nornir/.venv/lib/python3.10/site-packages/nornir/core/task.py", line 99, in start
    r = self.task(self, **self.params)
  File "/home/jcapps/nornir/runbook2.py", line 8, in show_command_test
    task.run(task=send_command, command="show ip interface brief")
  File "/home/jcapps/nornir/.venv/lib/python3.10/site-packages/nornir/core/task.py", line 174, in run
    raise NornirSubTaskError(task=run_task, result=r)
nornir.core.exceptions.NornirSubTaskError: Subtask: send_command (failed)


2022-07-09 13:46:32,805 -  nornir.core -     INFO -        run() - Running task 'show_command_test' with args {} on 4 hosts
2022-07-09 13:46:32,943 - nornir.core.task -    ERROR -      start() - Host 'R2': task 'send_command' failed with traceback:
Traceback (most recent call last):
  File "/home/jcapps/nornir/.venv/lib/python3.10/site-packages/nornir/core/task.py", line 99, in start
    r = self.task(self, **self.params)
  File "/home/jcapps/nornir/.venv/lib/python3.10/site-packages/nornir_scrapli/tasks/core/send_command.py", line 36, in send_command
    scrapli_conn = task.host.get_connection("scrapli", task.nornir.config)
  File "/home/jcapps/nornir/.venv/lib/python3.10/site-packages/nornir/core/inventory.py", line 494, in get_connection
    self.open_connection(
  File "/home/jcapps/nornir/.venv/lib/python3.10/site-packages/nornir/core/inventory.py", line 546, in open_connection
    conn_obj.open(
  File "/home/jcapps/nornir/.venv/lib/python3.10/site-packages/nornir_scrapli/connection.py", line 98, in open
    connection.open()
  File "/home/jcapps/nornir/.venv/lib/python3.10/site-packages/scrapli/driver/base/sync_driver.py", line 86, in open
    self.channel.channel_authenticate_ssh(
  File "/home/jcapps/nornir/.venv/lib/python3.10/site-packages/scrapli/decorators.py", line 280, in decorate
    return self._multiprocessing_timeout(
  File "/home/jcapps/nornir/.venv/lib/python3.10/site-packages/scrapli/decorators.py", line 341, in _multiprocessing_timeout
    return future.result()
  File "/usr/lib/python3.10/concurrent/futures/_base.py", line 439, in result
    return self.__get_result()
  File "/usr/lib/python3.10/concurrent/futures/_base.py", line 391, in __get_result
    raise self._exception
  File "/usr/lib/python3.10/concurrent/futures/thread.py", line 58, in run
    result = self.fn(*self.args, **self.kwargs)
  File "/home/jcapps/nornir/.venv/lib/python3.10/site-packages/scrapli/channel/sync_channel.py", line 290, in channel_authenticate_ssh
    self._ssh_message_handler(output=authenticate_buf)
  File "/home/jcapps/nornir/.venv/lib/python3.10/site-packages/scrapli/channel/base_channel.py", line 432, in _ssh_message_handler
    raise ScrapliAuthenticationFailed(msg)
scrapli.exceptions.ScrapliAuthenticationFailed: Host key verification failed

2022-07-09 13:46:32,943 - nornir.core.task -    ERROR -      start() - Host 'R2': task 'show_command_test' failed with traceback:
Traceback (most recent call last):
  File "/home/jcapps/nornir/.venv/lib/python3.10/site-packages/nornir/core/task.py", line 99, in start
    r = self.task(self, **self.params)
  File "/home/jcapps/nornir/runbook2.py", line 8, in show_command_test
    task.run(task=send_command, command="show ip interface brief")
  File "/home/jcapps/nornir/.venv/lib/python3.10/site-packages/nornir/core/task.py", line 174, in run
    raise NornirSubTaskError(task=run_task, result=r)
nornir.core.exceptions.NornirSubTaskError: Subtask: send_command (failed)


2022-07-09 13:46:32,947 - nornir.core.task -    ERROR -      start() - Host 'R1': task 'send_command' failed with traceback:
Traceback (most recent call last):
  File "/home/jcapps/nornir/.venv/lib/python3.10/site-packages/nornir/core/task.py", line 99, in start
    r = self.task(self, **self.params)
  File "/home/jcapps/nornir/.venv/lib/python3.10/site-packages/nornir_scrapli/tasks/core/send_command.py", line 36, in send_command
    scrapli_conn = task.host.get_connection("scrapli", task.nornir.config)
  File "/home/jcapps/nornir/.venv/lib/python3.10/site-packages/nornir/core/inventory.py", line 494, in get_connection
    self.open_connection(
  File "/home/jcapps/nornir/.venv/lib/python3.10/site-packages/nornir/core/inventory.py", line 546, in open_connection
    conn_obj.open(
  File "/home/jcapps/nornir/.venv/lib/python3.10/site-packages/nornir_scrapli/connection.py", line 98, in open
    connection.open()
  File "/home/jcapps/nornir/.venv/lib/python3.10/site-packages/scrapli/driver/base/sync_driver.py", line 86, in open
    self.channel.channel_authenticate_ssh(
  File "/home/jcapps/nornir/.venv/lib/python3.10/site-packages/scrapli/decorators.py", line 280, in decorate
    return self._multiprocessing_timeout(
  File "/home/jcapps/nornir/.venv/lib/python3.10/site-packages/scrapli/decorators.py", line 341, in _multiprocessing_timeout
    return future.result()
  File "/usr/lib/python3.10/concurrent/futures/_base.py", line 439, in result
    return self.__get_result()
  File "/usr/lib/python3.10/concurrent/futures/_base.py", line 391, in __get_result
    raise self._exception
  File "/usr/lib/python3.10/concurrent/futures/thread.py", line 58, in run
    result = self.fn(*self.args, **self.kwargs)
  File "/home/jcapps/nornir/.venv/lib/python3.10/site-packages/scrapli/channel/sync_channel.py", line 290, in channel_authenticate_ssh
    self._ssh_message_handler(output=authenticate_buf)
  File "/home/jcapps/nornir/.venv/lib/python3.10/site-packages/scrapli/channel/base_channel.py", line 432, in _ssh_message_handler
    raise ScrapliAuthenticationFailed(msg)
scrapli.exceptions.ScrapliAuthenticationFailed: Host key verification failed

2022-07-09 13:46:32,947 - nornir.core.task -    ERROR -      start() - Host 'R1': task 'show_command_test' failed with traceback:
Traceback (most recent call last):
  File "/home/jcapps/nornir/.venv/lib/python3.10/site-packages/nornir/core/task.py", line 99, in start
    r = self.task(self, **self.params)
  File "/home/jcapps/nornir/runbook2.py", line 8, in show_command_test
    task.run(task=send_command, command="show ip interface brief")
  File "/home/jcapps/nornir/.venv/lib/python3.10/site-packages/nornir/core/task.py", line 174, in run
    raise NornirSubTaskError(task=run_task, result=r)
nornir.core.exceptions.NornirSubTaskError: Subtask: send_command (failed)


2022-07-09 13:46:32,958 - nornir.core.task -    ERROR -      start() - Host 'R3': task 'send_command' failed with traceback:
Traceback (most recent call last):
  File "/home/jcapps/nornir/.venv/lib/python3.10/site-packages/nornir/core/task.py", line 99, in start
    r = self.task(self, **self.params)
  File "/home/jcapps/nornir/.venv/lib/python3.10/site-packages/nornir_scrapli/tasks/core/send_command.py", line 36, in send_command
    scrapli_conn = task.host.get_connection("scrapli", task.nornir.config)
  File "/home/jcapps/nornir/.venv/lib/python3.10/site-packages/nornir/core/inventory.py", line 494, in get_connection
    self.open_connection(
  File "/home/jcapps/nornir/.venv/lib/python3.10/site-packages/nornir/core/inventory.py", line 546, in open_connection
    conn_obj.open(
  File "/home/jcapps/nornir/.venv/lib/python3.10/site-packages/nornir_scrapli/connection.py", line 98, in open
    connection.open()
  File "/home/jcapps/nornir/.venv/lib/python3.10/site-packages/scrapli/driver/base/sync_driver.py", line 86, in open
    self.channel.channel_authenticate_ssh(
  File "/home/jcapps/nornir/.venv/lib/python3.10/site-packages/scrapli/decorators.py", line 280, in decorate
    return self._multiprocessing_timeout(
  File "/home/jcapps/nornir/.venv/lib/python3.10/site-packages/scrapli/decorators.py", line 341, in _multiprocessing_timeout
    return future.result()
  File "/usr/lib/python3.10/concurrent/futures/_base.py", line 439, in result
    return self.__get_result()
  File "/usr/lib/python3.10/concurrent/futures/_base.py", line 391, in __get_result
    raise self._exception
  File "/usr/lib/python3.10/concurrent/futures/thread.py", line 58, in run
    result = self.fn(*self.args, **self.kwargs)
  File "/home/jcapps/nornir/.venv/lib/python3.10/site-packages/scrapli/channel/sync_channel.py", line 290, in channel_authenticate_ssh
    self._ssh_message_handler(output=authenticate_buf)
  File "/home/jcapps/nornir/.venv/lib/python3.10/site-packages/scrapli/channel/base_channel.py", line 432, in _ssh_message_handler
    raise ScrapliAuthenticationFailed(msg)
scrapli.exceptions.ScrapliAuthenticationFailed: Host key verification failed

2022-07-09 13:46:32,958 - nornir.core.task -    ERROR -      start() - Host 'R3': task 'show_command_test' failed with traceback:
Traceback (most recent call last):
  File "/home/jcapps/nornir/.venv/lib/python3.10/site-packages/nornir/core/task.py", line 99, in start
    r = self.task(self, **self.params)
  File "/home/jcapps/nornir/runbook2.py", line 8, in show_command_test
    task.run(task=send_command, command="show ip interface brief")
  File "/home/jcapps/nornir/.venv/lib/python3.10/site-packages/nornir/core/task.py", line 174, in run
    raise NornirSubTaskError(task=run_task, result=r)
nornir.core.exceptions.NornirSubTaskError: Subtask: send_command (failed)


2022-07-09 13:46:32,979 - nornir.core.task -    ERROR -      start() - Host 'R4': task 'send_command' failed with traceback:
Traceback (most recent call last):
  File "/home/jcapps/nornir/.venv/lib/python3.10/site-packages/nornir/core/task.py", line 99, in start
    r = self.task(self, **self.params)
  File "/home/jcapps/nornir/.venv/lib/python3.10/site-packages/nornir_scrapli/tasks/core/send_command.py", line 36, in send_command
    scrapli_conn = task.host.get_connection("scrapli", task.nornir.config)
  File "/home/jcapps/nornir/.venv/lib/python3.10/site-packages/nornir/core/inventory.py", line 494, in get_connection
    self.open_connection(
  File "/home/jcapps/nornir/.venv/lib/python3.10/site-packages/nornir/core/inventory.py", line 546, in open_connection
    conn_obj.open(
  File "/home/jcapps/nornir/.venv/lib/python3.10/site-packages/nornir_scrapli/connection.py", line 98, in open
    connection.open()
  File "/home/jcapps/nornir/.venv/lib/python3.10/site-packages/scrapli/driver/base/sync_driver.py", line 86, in open
    self.channel.channel_authenticate_ssh(
  File "/home/jcapps/nornir/.venv/lib/python3.10/site-packages/scrapli/decorators.py", line 280, in decorate
    return self._multiprocessing_timeout(
  File "/home/jcapps/nornir/.venv/lib/python3.10/site-packages/scrapli/decorators.py", line 341, in _multiprocessing_timeout
    return future.result()
  File "/usr/lib/python3.10/concurrent/futures/_base.py", line 439, in result
    return self.__get_result()
  File "/usr/lib/python3.10/concurrent/futures/_base.py", line 391, in __get_result
    raise self._exception
  File "/usr/lib/python3.10/concurrent/futures/thread.py", line 58, in run
    result = self.fn(*self.args, **self.kwargs)
  File "/home/jcapps/nornir/.venv/lib/python3.10/site-packages/scrapli/channel/sync_channel.py", line 290, in channel_authenticate_ssh
    self._ssh_message_handler(output=authenticate_buf)
  File "/home/jcapps/nornir/.venv/lib/python3.10/site-packages/scrapli/channel/base_channel.py", line 432, in _ssh_message_handler
    raise ScrapliAuthenticationFailed(msg)
scrapli.exceptions.ScrapliAuthenticationFailed: Host key verification failed

2022-07-09 13:46:32,979 - nornir.core.task -    ERROR -      start() - Host 'R4': task 'show_command_test' failed with traceback:
Traceback (most recent call last):
  File "/home/jcapps/nornir/.venv/lib/python3.10/site-packages/nornir/core/task.py", line 99, in start
    r = self.task(self, **self.params)
  File "/home/jcapps/nornir/runbook2.py", line 8, in show_command_test
    task.run(task=send_command, command="show ip interface brief")
  File "/home/jcapps/nornir/.venv/lib/python3.10/site-packages/nornir/core/task.py", line 174, in run
    raise NornirSubTaskError(task=run_task, result=r)
nornir.core.exceptions.NornirSubTaskError: Subtask: send_command (failed)


2022-07-09 13:47:27,088 -  nornir.core -     INFO -        run() - Running task 'show_command_test' with args {} on 4 hosts
2022-07-09 13:51:13,735 -  nornir.core -     INFO -        run() - Running task 'show_commands_test' with args {} on 4 hosts
2022-07-09 13:51:15,603 - nornir.core.task -    ERROR -      start() - Host 'R3': task 'send_commands' failed with traceback:
Traceback (most recent call last):
  File "/home/jcapps/nornir/.venv/lib/python3.10/site-packages/nornir/core/task.py", line 99, in start
    r = self.task(self, **self.params)
  File "/home/jcapps/nornir/.venv/lib/python3.10/site-packages/nornir_scrapli/tasks/core/send_commands.py", line 44, in send_commands
    scrapli_response = scrapli_conn.send_commands(
  File "/home/jcapps/nornir/.venv/lib/python3.10/site-packages/scrapli/driver/network/sync_driver.py", line 291, in send_commands
    responses = super().send_commands(
  File "/home/jcapps/nornir/.venv/lib/python3.10/site-packages/scrapli/driver/generic/sync_driver.py", line 213, in send_commands
    responses = self._pre_send_commands(commands=commands)
  File "/home/jcapps/nornir/.venv/lib/python3.10/site-packages/scrapli/driver/generic/base_driver.py", line 313, in _pre_send_commands
    raise ScrapliTypeError(
scrapli.exceptions.ScrapliTypeError: `send_commands` expects a list of strings, got <class 'str'>, to send a single command use the `send_command` method instead.

2022-07-09 13:51:15,603 - nornir.core.task -    ERROR -      start() - Host 'R3': task 'show_commands_test' failed with traceback:
Traceback (most recent call last):
  File "/home/jcapps/nornir/.venv/lib/python3.10/site-packages/nornir/core/task.py", line 99, in start
    r = self.task(self, **self.params)
  File "/home/jcapps/nornir/runbook3.py", line 8, in show_commands_test
    task.run(task=send_commands, commands="[show ip interface brief, show version, show run]")
  File "/home/jcapps/nornir/.venv/lib/python3.10/site-packages/nornir/core/task.py", line 174, in run
    raise NornirSubTaskError(task=run_task, result=r)
nornir.core.exceptions.NornirSubTaskError: Subtask: send_commands (failed)


2022-07-09 13:51:16,339 - nornir.core.task -    ERROR -      start() - Host 'R1': task 'send_commands' failed with traceback:
Traceback (most recent call last):
  File "/home/jcapps/nornir/.venv/lib/python3.10/site-packages/nornir/core/task.py", line 99, in start
    r = self.task(self, **self.params)
  File "/home/jcapps/nornir/.venv/lib/python3.10/site-packages/nornir_scrapli/tasks/core/send_commands.py", line 44, in send_commands
    scrapli_response = scrapli_conn.send_commands(
  File "/home/jcapps/nornir/.venv/lib/python3.10/site-packages/scrapli/driver/network/sync_driver.py", line 291, in send_commands
    responses = super().send_commands(
  File "/home/jcapps/nornir/.venv/lib/python3.10/site-packages/scrapli/driver/generic/sync_driver.py", line 213, in send_commands
    responses = self._pre_send_commands(commands=commands)
  File "/home/jcapps/nornir/.venv/lib/python3.10/site-packages/scrapli/driver/generic/base_driver.py", line 313, in _pre_send_commands
    raise ScrapliTypeError(
scrapli.exceptions.ScrapliTypeError: `send_commands` expects a list of strings, got <class 'str'>, to send a single command use the `send_command` method instead.

2022-07-09 13:51:16,339 - nornir.core.task -    ERROR -      start() - Host 'R1': task 'show_commands_test' failed with traceback:
Traceback (most recent call last):
  File "/home/jcapps/nornir/.venv/lib/python3.10/site-packages/nornir/core/task.py", line 99, in start
    r = self.task(self, **self.params)
  File "/home/jcapps/nornir/runbook3.py", line 8, in show_commands_test
    task.run(task=send_commands, commands="[show ip interface brief, show version, show run]")
  File "/home/jcapps/nornir/.venv/lib/python3.10/site-packages/nornir/core/task.py", line 174, in run
    raise NornirSubTaskError(task=run_task, result=r)
nornir.core.exceptions.NornirSubTaskError: Subtask: send_commands (failed)


2022-07-09 13:51:16,379 - nornir.core.task -    ERROR -      start() - Host 'R4': task 'send_commands' failed with traceback:
Traceback (most recent call last):
  File "/home/jcapps/nornir/.venv/lib/python3.10/site-packages/nornir/core/task.py", line 99, in start
    r = self.task(self, **self.params)
  File "/home/jcapps/nornir/.venv/lib/python3.10/site-packages/nornir_scrapli/tasks/core/send_commands.py", line 44, in send_commands
    scrapli_response = scrapli_conn.send_commands(
  File "/home/jcapps/nornir/.venv/lib/python3.10/site-packages/scrapli/driver/network/sync_driver.py", line 291, in send_commands
    responses = super().send_commands(
  File "/home/jcapps/nornir/.venv/lib/python3.10/site-packages/scrapli/driver/generic/sync_driver.py", line 213, in send_commands
    responses = self._pre_send_commands(commands=commands)
  File "/home/jcapps/nornir/.venv/lib/python3.10/site-packages/scrapli/driver/generic/base_driver.py", line 313, in _pre_send_commands
    raise ScrapliTypeError(
scrapli.exceptions.ScrapliTypeError: `send_commands` expects a list of strings, got <class 'str'>, to send a single command use the `send_command` method instead.

2022-07-09 13:51:16,379 - nornir.core.task -    ERROR -      start() - Host 'R4': task 'show_commands_test' failed with traceback:
Traceback (most recent call last):
  File "/home/jcapps/nornir/.venv/lib/python3.10/site-packages/nornir/core/task.py", line 99, in start
    r = self.task(self, **self.params)
  File "/home/jcapps/nornir/runbook3.py", line 8, in show_commands_test
    task.run(task=send_commands, commands="[show ip interface brief, show version, show run]")
  File "/home/jcapps/nornir/.venv/lib/python3.10/site-packages/nornir/core/task.py", line 174, in run
    raise NornirSubTaskError(task=run_task, result=r)
nornir.core.exceptions.NornirSubTaskError: Subtask: send_commands (failed)


2022-07-09 13:51:17,365 - nornir.core.task -    ERROR -      start() - Host 'R2': task 'send_commands' failed with traceback:
Traceback (most recent call last):
  File "/home/jcapps/nornir/.venv/lib/python3.10/site-packages/nornir/core/task.py", line 99, in start
    r = self.task(self, **self.params)
  File "/home/jcapps/nornir/.venv/lib/python3.10/site-packages/nornir_scrapli/tasks/core/send_commands.py", line 44, in send_commands
    scrapli_response = scrapli_conn.send_commands(
  File "/home/jcapps/nornir/.venv/lib/python3.10/site-packages/scrapli/driver/network/sync_driver.py", line 291, in send_commands
    responses = super().send_commands(
  File "/home/jcapps/nornir/.venv/lib/python3.10/site-packages/scrapli/driver/generic/sync_driver.py", line 213, in send_commands
    responses = self._pre_send_commands(commands=commands)
  File "/home/jcapps/nornir/.venv/lib/python3.10/site-packages/scrapli/driver/generic/base_driver.py", line 313, in _pre_send_commands
    raise ScrapliTypeError(
scrapli.exceptions.ScrapliTypeError: `send_commands` expects a list of strings, got <class 'str'>, to send a single command use the `send_command` method instead.

2022-07-09 13:51:17,365 - nornir.core.task -    ERROR -      start() - Host 'R2': task 'show_commands_test' failed with traceback:
Traceback (most recent call last):
  File "/home/jcapps/nornir/.venv/lib/python3.10/site-packages/nornir/core/task.py", line 99, in start
    r = self.task(self, **self.params)
  File "/home/jcapps/nornir/runbook3.py", line 8, in show_commands_test
    task.run(task=send_commands, commands="[show ip interface brief, show version, show run]")
  File "/home/jcapps/nornir/.venv/lib/python3.10/site-packages/nornir/core/task.py", line 174, in run
    raise NornirSubTaskError(task=run_task, result=r)
nornir.core.exceptions.NornirSubTaskError: Subtask: send_commands (failed)


2022-07-09 13:52:07,291 -  nornir.core -     INFO -        run() - Running task 'show_commands_test' with args {} on 4 hosts
