2022-07-09 12:03:04,718 -  nornir.core -     INFO -        run() - Running task 'send_command' with args {'command': 'show version'} on 5 hosts
2022-07-09 12:03:04,793 - nornir.core.task -    ERROR -      start() - Host 'R3': task 'send_command' failed with traceback:
Traceback (most recent call last):
  File "/home/jcapps/nornir/.venv/lib/python3.10/site-packages/scrapli/transport/plugins/system/ptyprocess.py", line 488, in read
    s = self.fileobj.read1(size)
OSError: [Errno 5] Input/output error

During handling of the above exception, another exception occurred:

Traceback (most recent call last):
  File "/home/jcapps/nornir/.venv/lib/python3.10/site-packages/scrapli/transport/plugins/system/transport.py", line 158, in read
    buf = self.session.read(65535)
  File "/home/jcapps/nornir/.venv/lib/python3.10/site-packages/scrapli/transport/plugins/system/ptyprocess.py", line 493, in read
    raise EOFError("End Of File (EOF). Exception style platform.")
EOFError: End Of File (EOF). Exception style platform.

The above exception was the direct cause of the following exception:

Traceback (most recent call last):
  File "/home/jcapps/nornir/.venv/lib/python3.10/site-packages/nornir/core/task.py", line 99, in start
    r = self.task(self, **self.params)
  File "/home/jcapps/nornir/.venv/lib/python3.10/site-packages/nornir_scrapli/tasks/core/send_command.py", line 36, in send_command
    scrapli_conn = task.host.get_connection("scrapli", task.nornir.config)
  File "/home/jcapps/nornir/.venv/lib/python3.10/site-packages/nornir/core/inventory.py", line 494, in get_connection
    self.open_connection(
  File "/home/jcapps/nornir/.venv/lib/python3.10/site-packages/nornir/core/inventory.py", line 546, in open_connection
    conn_obj.open(
  File "/home/jcapps/nornir/.venv/lib/python3.10/site-packages/nornir_scrapli/connection.py", line 98, in open
    connection.open()
  File "/home/jcapps/nornir/.venv/lib/python3.10/site-packages/scrapli/driver/base/sync_driver.py", line 86, in open
    self.channel.channel_authenticate_ssh(
  File "/home/jcapps/nornir/.venv/lib/python3.10/site-packages/scrapli/decorators.py", line 280, in decorate
    return self._multiprocessing_timeout(
  File "/home/jcapps/nornir/.venv/lib/python3.10/site-packages/scrapli/decorators.py", line 341, in _multiprocessing_timeout
    return future.result()
  File "/usr/lib/python3.10/concurrent/futures/_base.py", line 439, in result
    return self.__get_result()
  File "/usr/lib/python3.10/concurrent/futures/_base.py", line 391, in __get_result
    raise self._exception
  File "/usr/lib/python3.10/concurrent/futures/thread.py", line 58, in run
    result = self.fn(*self.args, **self.kwargs)
  File "/home/jcapps/nornir/.venv/lib/python3.10/site-packages/scrapli/channel/sync_channel.py", line 287, in channel_authenticate_ssh
    buf = self.read()
  File "/home/jcapps/nornir/.venv/lib/python3.10/site-packages/scrapli/channel/sync_channel.py", line 69, in read
    buf = self.transport.read()
  File "/home/jcapps/nornir/.venv/lib/python3.10/site-packages/scrapli/decorators.py", line 99, in decorate
    return self._multiprocessing_timeout(
  File "/home/jcapps/nornir/.venv/lib/python3.10/site-packages/scrapli/decorators.py", line 177, in _multiprocessing_timeout
    return future.result()
  File "/usr/lib/python3.10/concurrent/futures/_base.py", line 439, in result
    return self.__get_result()
  File "/usr/lib/python3.10/concurrent/futures/_base.py", line 391, in __get_result
    raise self._exception
  File "/usr/lib/python3.10/concurrent/futures/thread.py", line 58, in run
    result = self.fn(*self.args, **self.kwargs)
  File "/home/jcapps/nornir/.venv/lib/python3.10/site-packages/scrapli/transport/plugins/system/transport.py", line 165, in read
    raise ScrapliConnectionError(msg) from exc
scrapli.exceptions.ScrapliConnectionError: encountered EOF reading from transport; typically means the device closed the connection

2022-07-09 12:03:04,898 - nornir.core.task -    ERROR -      start() - Host 'R2': task 'send_command' failed with traceback:
Traceback (most recent call last):
  File "/home/jcapps/nornir/.venv/lib/python3.10/site-packages/nornir/core/task.py", line 99, in start
    r = self.task(self, **self.params)
  File "/home/jcapps/nornir/.venv/lib/python3.10/site-packages/nornir_scrapli/tasks/core/send_command.py", line 36, in send_command
    scrapli_conn = task.host.get_connection("scrapli", task.nornir.config)
  File "/home/jcapps/nornir/.venv/lib/python3.10/site-packages/nornir/core/inventory.py", line 494, in get_connection
    self.open_connection(
  File "/home/jcapps/nornir/.venv/lib/python3.10/site-packages/nornir/core/inventory.py", line 546, in open_connection
    conn_obj.open(
  File "/home/jcapps/nornir/.venv/lib/python3.10/site-packages/nornir_scrapli/connection.py", line 98, in open
    connection.open()
  File "/home/jcapps/nornir/.venv/lib/python3.10/site-packages/scrapli/driver/base/sync_driver.py", line 86, in open
    self.channel.channel_authenticate_ssh(
  File "/home/jcapps/nornir/.venv/lib/python3.10/site-packages/scrapli/decorators.py", line 280, in decorate
    return self._multiprocessing_timeout(
  File "/home/jcapps/nornir/.venv/lib/python3.10/site-packages/scrapli/decorators.py", line 341, in _multiprocessing_timeout
    return future.result()
  File "/usr/lib/python3.10/concurrent/futures/_base.py", line 439, in result
    return self.__get_result()
  File "/usr/lib/python3.10/concurrent/futures/_base.py", line 391, in __get_result
    raise self._exception
  File "/usr/lib/python3.10/concurrent/futures/thread.py", line 58, in run
    result = self.fn(*self.args, **self.kwargs)
  File "/home/jcapps/nornir/.venv/lib/python3.10/site-packages/scrapli/channel/sync_channel.py", line 290, in channel_authenticate_ssh
    self._ssh_message_handler(output=authenticate_buf)
  File "/home/jcapps/nornir/.venv/lib/python3.10/site-packages/scrapli/channel/base_channel.py", line 432, in _ssh_message_handler
    raise ScrapliAuthenticationFailed(msg)
scrapli.exceptions.ScrapliAuthenticationFailed: Host key verification failed

2022-07-09 12:03:04,911 - nornir.core.task -    ERROR -      start() - Host 'R5': task 'send_command' failed with traceback:
Traceback (most recent call last):
  File "/home/jcapps/nornir/.venv/lib/python3.10/site-packages/nornir/core/task.py", line 99, in start
    r = self.task(self, **self.params)
  File "/home/jcapps/nornir/.venv/lib/python3.10/site-packages/nornir_scrapli/tasks/core/send_command.py", line 36, in send_command
    scrapli_conn = task.host.get_connection("scrapli", task.nornir.config)
  File "/home/jcapps/nornir/.venv/lib/python3.10/site-packages/nornir/core/inventory.py", line 494, in get_connection
    self.open_connection(
  File "/home/jcapps/nornir/.venv/lib/python3.10/site-packages/nornir/core/inventory.py", line 546, in open_connection
    conn_obj.open(
  File "/home/jcapps/nornir/.venv/lib/python3.10/site-packages/nornir_scrapli/connection.py", line 98, in open
    connection.open()
  File "/home/jcapps/nornir/.venv/lib/python3.10/site-packages/scrapli/driver/base/sync_driver.py", line 86, in open
    self.channel.channel_authenticate_ssh(
  File "/home/jcapps/nornir/.venv/lib/python3.10/site-packages/scrapli/decorators.py", line 280, in decorate
    return self._multiprocessing_timeout(
  File "/home/jcapps/nornir/.venv/lib/python3.10/site-packages/scrapli/decorators.py", line 341, in _multiprocessing_timeout
    return future.result()
  File "/usr/lib/python3.10/concurrent/futures/_base.py", line 439, in result
    return self.__get_result()
  File "/usr/lib/python3.10/concurrent/futures/_base.py", line 391, in __get_result
    raise self._exception
  File "/usr/lib/python3.10/concurrent/futures/thread.py", line 58, in run
    result = self.fn(*self.args, **self.kwargs)
  File "/home/jcapps/nornir/.venv/lib/python3.10/site-packages/scrapli/channel/sync_channel.py", line 290, in channel_authenticate_ssh
    self._ssh_message_handler(output=authenticate_buf)
  File "/home/jcapps/nornir/.venv/lib/python3.10/site-packages/scrapli/channel/base_channel.py", line 432, in _ssh_message_handler
    raise ScrapliAuthenticationFailed(msg)
scrapli.exceptions.ScrapliAuthenticationFailed: Host key verification failed

2022-07-09 12:03:04,920 - nornir.core.task -    ERROR -      start() - Host 'R1': task 'send_command' failed with traceback:
Traceback (most recent call last):
  File "/home/jcapps/nornir/.venv/lib/python3.10/site-packages/nornir/core/task.py", line 99, in start
    r = self.task(self, **self.params)
  File "/home/jcapps/nornir/.venv/lib/python3.10/site-packages/nornir_scrapli/tasks/core/send_command.py", line 36, in send_command
    scrapli_conn = task.host.get_connection("scrapli", task.nornir.config)
  File "/home/jcapps/nornir/.venv/lib/python3.10/site-packages/nornir/core/inventory.py", line 494, in get_connection
    self.open_connection(
  File "/home/jcapps/nornir/.venv/lib/python3.10/site-packages/nornir/core/inventory.py", line 546, in open_connection
    conn_obj.open(
  File "/home/jcapps/nornir/.venv/lib/python3.10/site-packages/nornir_scrapli/connection.py", line 98, in open
    connection.open()
  File "/home/jcapps/nornir/.venv/lib/python3.10/site-packages/scrapli/driver/base/sync_driver.py", line 86, in open
    self.channel.channel_authenticate_ssh(
  File "/home/jcapps/nornir/.venv/lib/python3.10/site-packages/scrapli/decorators.py", line 280, in decorate
    return self._multiprocessing_timeout(
  File "/home/jcapps/nornir/.venv/lib/python3.10/site-packages/scrapli/decorators.py", line 341, in _multiprocessing_timeout
    return future.result()
  File "/usr/lib/python3.10/concurrent/futures/_base.py", line 439, in result
    return self.__get_result()
  File "/usr/lib/python3.10/concurrent/futures/_base.py", line 391, in __get_result
    raise self._exception
  File "/usr/lib/python3.10/concurrent/futures/thread.py", line 58, in run
    result = self.fn(*self.args, **self.kwargs)
  File "/home/jcapps/nornir/.venv/lib/python3.10/site-packages/scrapli/channel/sync_channel.py", line 290, in channel_authenticate_ssh
    self._ssh_message_handler(output=authenticate_buf)
  File "/home/jcapps/nornir/.venv/lib/python3.10/site-packages/scrapli/channel/base_channel.py", line 432, in _ssh_message_handler
    raise ScrapliAuthenticationFailed(msg)
scrapli.exceptions.ScrapliAuthenticationFailed: Host key verification failed

2022-07-09 12:03:05,108 - nornir.core.task -    ERROR -      start() - Host 'R4': task 'send_command' failed with traceback:
Traceback (most recent call last):
  File "/home/jcapps/nornir/.venv/lib/python3.10/site-packages/nornir/core/task.py", line 99, in start
    r = self.task(self, **self.params)
  File "/home/jcapps/nornir/.venv/lib/python3.10/site-packages/nornir_scrapli/tasks/core/send_command.py", line 36, in send_command
    scrapli_conn = task.host.get_connection("scrapli", task.nornir.config)
  File "/home/jcapps/nornir/.venv/lib/python3.10/site-packages/nornir/core/inventory.py", line 494, in get_connection
    self.open_connection(
  File "/home/jcapps/nornir/.venv/lib/python3.10/site-packages/nornir/core/inventory.py", line 546, in open_connection
    conn_obj.open(
  File "/home/jcapps/nornir/.venv/lib/python3.10/site-packages/nornir_scrapli/connection.py", line 98, in open
    connection.open()
  File "/home/jcapps/nornir/.venv/lib/python3.10/site-packages/scrapli/driver/base/sync_driver.py", line 86, in open
    self.channel.channel_authenticate_ssh(
  File "/home/jcapps/nornir/.venv/lib/python3.10/site-packages/scrapli/decorators.py", line 280, in decorate
    return self._multiprocessing_timeout(
  File "/home/jcapps/nornir/.venv/lib/python3.10/site-packages/scrapli/decorators.py", line 341, in _multiprocessing_timeout
    return future.result()
  File "/usr/lib/python3.10/concurrent/futures/_base.py", line 439, in result
    return self.__get_result()
  File "/usr/lib/python3.10/concurrent/futures/_base.py", line 391, in __get_result
    raise self._exception
  File "/usr/lib/python3.10/concurrent/futures/thread.py", line 58, in run
    result = self.fn(*self.args, **self.kwargs)
  File "/home/jcapps/nornir/.venv/lib/python3.10/site-packages/scrapli/channel/sync_channel.py", line 290, in channel_authenticate_ssh
    self._ssh_message_handler(output=authenticate_buf)
  File "/home/jcapps/nornir/.venv/lib/python3.10/site-packages/scrapli/channel/base_channel.py", line 432, in _ssh_message_handler
    raise ScrapliAuthenticationFailed(msg)
scrapli.exceptions.ScrapliAuthenticationFailed: Host key verification failed

2022-07-09 12:03:23,868 -  nornir.core -     INFO -        run() - Running task 'send_command' with args {'command': 'show version'} on 5 hosts
2022-07-09 12:03:23,965 - nornir.core.task -    ERROR -      start() - Host 'R3': task 'send_command' failed with traceback:
Traceback (most recent call last):
  File "/home/jcapps/nornir/.venv/lib/python3.10/site-packages/scrapli/transport/plugins/system/ptyprocess.py", line 488, in read
    s = self.fileobj.read1(size)
OSError: [Errno 5] Input/output error

During handling of the above exception, another exception occurred:

Traceback (most recent call last):
  File "/home/jcapps/nornir/.venv/lib/python3.10/site-packages/scrapli/transport/plugins/system/transport.py", line 158, in read
    buf = self.session.read(65535)
  File "/home/jcapps/nornir/.venv/lib/python3.10/site-packages/scrapli/transport/plugins/system/ptyprocess.py", line 493, in read
    raise EOFError("End Of File (EOF). Exception style platform.")
EOFError: End Of File (EOF). Exception style platform.

The above exception was the direct cause of the following exception:

Traceback (most recent call last):
  File "/home/jcapps/nornir/.venv/lib/python3.10/site-packages/nornir/core/task.py", line 99, in start
    r = self.task(self, **self.params)
  File "/home/jcapps/nornir/.venv/lib/python3.10/site-packages/nornir_scrapli/tasks/core/send_command.py", line 36, in send_command
    scrapli_conn = task.host.get_connection("scrapli", task.nornir.config)
  File "/home/jcapps/nornir/.venv/lib/python3.10/site-packages/nornir/core/inventory.py", line 494, in get_connection
    self.open_connection(
  File "/home/jcapps/nornir/.venv/lib/python3.10/site-packages/nornir/core/inventory.py", line 546, in open_connection
    conn_obj.open(
  File "/home/jcapps/nornir/.venv/lib/python3.10/site-packages/nornir_scrapli/connection.py", line 98, in open
    connection.open()
  File "/home/jcapps/nornir/.venv/lib/python3.10/site-packages/scrapli/driver/base/sync_driver.py", line 86, in open
    self.channel.channel_authenticate_ssh(
  File "/home/jcapps/nornir/.venv/lib/python3.10/site-packages/scrapli/decorators.py", line 280, in decorate
    return self._multiprocessing_timeout(
  File "/home/jcapps/nornir/.venv/lib/python3.10/site-packages/scrapli/decorators.py", line 341, in _multiprocessing_timeout
    return future.result()
  File "/usr/lib/python3.10/concurrent/futures/_base.py", line 439, in result
    return self.__get_result()
  File "/usr/lib/python3.10/concurrent/futures/_base.py", line 391, in __get_result
    raise self._exception
  File "/usr/lib/python3.10/concurrent/futures/thread.py", line 58, in run
    result = self.fn(*self.args, **self.kwargs)
  File "/home/jcapps/nornir/.venv/lib/python3.10/site-packages/scrapli/channel/sync_channel.py", line 287, in channel_authenticate_ssh
    buf = self.read()
  File "/home/jcapps/nornir/.venv/lib/python3.10/site-packages/scrapli/channel/sync_channel.py", line 69, in read
    buf = self.transport.read()
  File "/home/jcapps/nornir/.venv/lib/python3.10/site-packages/scrapli/decorators.py", line 99, in decorate
    return self._multiprocessing_timeout(
  File "/home/jcapps/nornir/.venv/lib/python3.10/site-packages/scrapli/decorators.py", line 177, in _multiprocessing_timeout
    return future.result()
  File "/usr/lib/python3.10/concurrent/futures/_base.py", line 439, in result
    return self.__get_result()
  File "/usr/lib/python3.10/concurrent/futures/_base.py", line 391, in __get_result
    raise self._exception
  File "/usr/lib/python3.10/concurrent/futures/thread.py", line 58, in run
    result = self.fn(*self.args, **self.kwargs)
  File "/home/jcapps/nornir/.venv/lib/python3.10/site-packages/scrapli/transport/plugins/system/transport.py", line 165, in read
    raise ScrapliConnectionError(msg) from exc
scrapli.exceptions.ScrapliConnectionError: encountered EOF reading from transport; typically means the device closed the connection

2022-07-09 12:03:24,044 - nornir.core.task -    ERROR -      start() - Host 'R1': task 'send_command' failed with traceback:
Traceback (most recent call last):
  File "/home/jcapps/nornir/.venv/lib/python3.10/site-packages/nornir/core/task.py", line 99, in start
    r = self.task(self, **self.params)
  File "/home/jcapps/nornir/.venv/lib/python3.10/site-packages/nornir_scrapli/tasks/core/send_command.py", line 36, in send_command
    scrapli_conn = task.host.get_connection("scrapli", task.nornir.config)
  File "/home/jcapps/nornir/.venv/lib/python3.10/site-packages/nornir/core/inventory.py", line 494, in get_connection
    self.open_connection(
  File "/home/jcapps/nornir/.venv/lib/python3.10/site-packages/nornir/core/inventory.py", line 546, in open_connection
    conn_obj.open(
  File "/home/jcapps/nornir/.venv/lib/python3.10/site-packages/nornir_scrapli/connection.py", line 98, in open
    connection.open()
  File "/home/jcapps/nornir/.venv/lib/python3.10/site-packages/scrapli/driver/base/sync_driver.py", line 86, in open
    self.channel.channel_authenticate_ssh(
  File "/home/jcapps/nornir/.venv/lib/python3.10/site-packages/scrapli/decorators.py", line 280, in decorate
    return self._multiprocessing_timeout(
  File "/home/jcapps/nornir/.venv/lib/python3.10/site-packages/scrapli/decorators.py", line 341, in _multiprocessing_timeout
    return future.result()
  File "/usr/lib/python3.10/concurrent/futures/_base.py", line 439, in result
    return self.__get_result()
  File "/usr/lib/python3.10/concurrent/futures/_base.py", line 391, in __get_result
    raise self._exception
  File "/usr/lib/python3.10/concurrent/futures/thread.py", line 58, in run
    result = self.fn(*self.args, **self.kwargs)
  File "/home/jcapps/nornir/.venv/lib/python3.10/site-packages/scrapli/channel/sync_channel.py", line 290, in channel_authenticate_ssh
    self._ssh_message_handler(output=authenticate_buf)
  File "/home/jcapps/nornir/.venv/lib/python3.10/site-packages/scrapli/channel/base_channel.py", line 432, in _ssh_message_handler
    raise ScrapliAuthenticationFailed(msg)
scrapli.exceptions.ScrapliAuthenticationFailed: Host key verification failed

2022-07-09 12:03:24,224 - nornir.core.task -    ERROR -      start() - Host 'R4': task 'send_command' failed with traceback:
Traceback (most recent call last):
  File "/home/jcapps/nornir/.venv/lib/python3.10/site-packages/nornir/core/task.py", line 99, in start
    r = self.task(self, **self.params)
  File "/home/jcapps/nornir/.venv/lib/python3.10/site-packages/nornir_scrapli/tasks/core/send_command.py", line 36, in send_command
    scrapli_conn = task.host.get_connection("scrapli", task.nornir.config)
  File "/home/jcapps/nornir/.venv/lib/python3.10/site-packages/nornir/core/inventory.py", line 494, in get_connection
    self.open_connection(
  File "/home/jcapps/nornir/.venv/lib/python3.10/site-packages/nornir/core/inventory.py", line 546, in open_connection
    conn_obj.open(
  File "/home/jcapps/nornir/.venv/lib/python3.10/site-packages/nornir_scrapli/connection.py", line 98, in open
    connection.open()
  File "/home/jcapps/nornir/.venv/lib/python3.10/site-packages/scrapli/driver/base/sync_driver.py", line 86, in open
    self.channel.channel_authenticate_ssh(
  File "/home/jcapps/nornir/.venv/lib/python3.10/site-packages/scrapli/decorators.py", line 280, in decorate
    return self._multiprocessing_timeout(
  File "/home/jcapps/nornir/.venv/lib/python3.10/site-packages/scrapli/decorators.py", line 341, in _multiprocessing_timeout
    return future.result()
  File "/usr/lib/python3.10/concurrent/futures/_base.py", line 439, in result
    return self.__get_result()
  File "/usr/lib/python3.10/concurrent/futures/_base.py", line 391, in __get_result
    raise self._exception
  File "/usr/lib/python3.10/concurrent/futures/thread.py", line 58, in run
    result = self.fn(*self.args, **self.kwargs)
  File "/home/jcapps/nornir/.venv/lib/python3.10/site-packages/scrapli/channel/sync_channel.py", line 290, in channel_authenticate_ssh
    self._ssh_message_handler(output=authenticate_buf)
  File "/home/jcapps/nornir/.venv/lib/python3.10/site-packages/scrapli/channel/base_channel.py", line 432, in _ssh_message_handler
    raise ScrapliAuthenticationFailed(msg)
scrapli.exceptions.ScrapliAuthenticationFailed: Host key verification failed

2022-07-09 12:03:24,265 - nornir.core.task -    ERROR -      start() - Host 'R5': task 'send_command' failed with traceback:
Traceback (most recent call last):
  File "/home/jcapps/nornir/.venv/lib/python3.10/site-packages/nornir/core/task.py", line 99, in start
    r = self.task(self, **self.params)
  File "/home/jcapps/nornir/.venv/lib/python3.10/site-packages/nornir_scrapli/tasks/core/send_command.py", line 36, in send_command
    scrapli_conn = task.host.get_connection("scrapli", task.nornir.config)
  File "/home/jcapps/nornir/.venv/lib/python3.10/site-packages/nornir/core/inventory.py", line 494, in get_connection
    self.open_connection(
  File "/home/jcapps/nornir/.venv/lib/python3.10/site-packages/nornir/core/inventory.py", line 546, in open_connection
    conn_obj.open(
  File "/home/jcapps/nornir/.venv/lib/python3.10/site-packages/nornir_scrapli/connection.py", line 98, in open
    connection.open()
  File "/home/jcapps/nornir/.venv/lib/python3.10/site-packages/scrapli/driver/base/sync_driver.py", line 86, in open
    self.channel.channel_authenticate_ssh(
  File "/home/jcapps/nornir/.venv/lib/python3.10/site-packages/scrapli/decorators.py", line 280, in decorate
    return self._multiprocessing_timeout(
  File "/home/jcapps/nornir/.venv/lib/python3.10/site-packages/scrapli/decorators.py", line 341, in _multiprocessing_timeout
    return future.result()
  File "/usr/lib/python3.10/concurrent/futures/_base.py", line 439, in result
    return self.__get_result()
  File "/usr/lib/python3.10/concurrent/futures/_base.py", line 391, in __get_result
    raise self._exception
  File "/usr/lib/python3.10/concurrent/futures/thread.py", line 58, in run
    result = self.fn(*self.args, **self.kwargs)
  File "/home/jcapps/nornir/.venv/lib/python3.10/site-packages/scrapli/channel/sync_channel.py", line 290, in channel_authenticate_ssh
    self._ssh_message_handler(output=authenticate_buf)
  File "/home/jcapps/nornir/.venv/lib/python3.10/site-packages/scrapli/channel/base_channel.py", line 432, in _ssh_message_handler
    raise ScrapliAuthenticationFailed(msg)
scrapli.exceptions.ScrapliAuthenticationFailed: Host key verification failed

2022-07-09 12:03:24,313 - nornir.core.task -    ERROR -      start() - Host 'R2': task 'send_command' failed with traceback:
Traceback (most recent call last):
  File "/home/jcapps/nornir/.venv/lib/python3.10/site-packages/nornir/core/task.py", line 99, in start
    r = self.task(self, **self.params)
  File "/home/jcapps/nornir/.venv/lib/python3.10/site-packages/nornir_scrapli/tasks/core/send_command.py", line 36, in send_command
    scrapli_conn = task.host.get_connection("scrapli", task.nornir.config)
  File "/home/jcapps/nornir/.venv/lib/python3.10/site-packages/nornir/core/inventory.py", line 494, in get_connection
    self.open_connection(
  File "/home/jcapps/nornir/.venv/lib/python3.10/site-packages/nornir/core/inventory.py", line 546, in open_connection
    conn_obj.open(
  File "/home/jcapps/nornir/.venv/lib/python3.10/site-packages/nornir_scrapli/connection.py", line 98, in open
    connection.open()
  File "/home/jcapps/nornir/.venv/lib/python3.10/site-packages/scrapli/driver/base/sync_driver.py", line 86, in open
    self.channel.channel_authenticate_ssh(
  File "/home/jcapps/nornir/.venv/lib/python3.10/site-packages/scrapli/decorators.py", line 280, in decorate
    return self._multiprocessing_timeout(
  File "/home/jcapps/nornir/.venv/lib/python3.10/site-packages/scrapli/decorators.py", line 341, in _multiprocessing_timeout
    return future.result()
  File "/usr/lib/python3.10/concurrent/futures/_base.py", line 439, in result
    return self.__get_result()
  File "/usr/lib/python3.10/concurrent/futures/_base.py", line 391, in __get_result
    raise self._exception
  File "/usr/lib/python3.10/concurrent/futures/thread.py", line 58, in run
    result = self.fn(*self.args, **self.kwargs)
  File "/home/jcapps/nornir/.venv/lib/python3.10/site-packages/scrapli/channel/sync_channel.py", line 290, in channel_authenticate_ssh
    self._ssh_message_handler(output=authenticate_buf)
  File "/home/jcapps/nornir/.venv/lib/python3.10/site-packages/scrapli/channel/base_channel.py", line 432, in _ssh_message_handler
    raise ScrapliAuthenticationFailed(msg)
scrapli.exceptions.ScrapliAuthenticationFailed: Host key verification failed

2022-07-09 12:05:37,370 -  nornir.core -     INFO -        run() - Running task 'send_command' with args {'command': 'show version'} on 5 hosts
2022-07-09 12:09:03,690 -  nornir.core -     INFO -        run() - Running task 'send_command' with args {'command': 'show version'} on 4 hosts
2022-07-09 12:13:13,866 -  nornir.core -     INFO -        run() - Running task 'send_command' with args {'command': 'show version'} on 4 hosts
2022-07-09 12:13:13,874 - nornir.core.task -    ERROR -      start() - Host 'R4': task 'send_command' failed with traceback:
Traceback (most recent call last):
  File "/home/jcapps/nornir/.venv/lib/python3.10/site-packages/nornir/core/task.py", line 99, in start
    r = self.task(self, **self.params)
  File "/home/jcapps/nornir/.venv/lib/python3.10/site-packages/nornir_scrapli/tasks/core/send_command.py", line 36, in send_command
    scrapli_conn = task.host.get_connection("scrapli", task.nornir.config)
  File "/home/jcapps/nornir/.venv/lib/python3.10/site-packages/nornir/core/inventory.py", line 494, in get_connection
    self.open_connection(
  File "/home/jcapps/nornir/.venv/lib/python3.10/site-packages/nornir/core/inventory.py", line 546, in open_connection
    conn_obj.open(
  File "/home/jcapps/nornir/.venv/lib/python3.10/site-packages/nornir_scrapli/connection.py", line 81, in open
    raise NornirScrapliInvalidPlatform(
nornir_scrapli.exceptions.NornirScrapliInvalidPlatform: 'platform' not provided in inventory for host `192.168.1.14`

2022-07-09 12:13:13,874 - nornir.core.task -    ERROR -      start() - Host 'R1': task 'send_command' failed with traceback:
Traceback (most recent call last):
  File "/home/jcapps/nornir/.venv/lib/python3.10/site-packages/nornir/core/task.py", line 99, in start
    r = self.task(self, **self.params)
  File "/home/jcapps/nornir/.venv/lib/python3.10/site-packages/nornir_scrapli/tasks/core/send_command.py", line 36, in send_command
    scrapli_conn = task.host.get_connection("scrapli", task.nornir.config)
  File "/home/jcapps/nornir/.venv/lib/python3.10/site-packages/nornir/core/inventory.py", line 494, in get_connection
    self.open_connection(
  File "/home/jcapps/nornir/.venv/lib/python3.10/site-packages/nornir/core/inventory.py", line 546, in open_connection
    conn_obj.open(
  File "/home/jcapps/nornir/.venv/lib/python3.10/site-packages/nornir_scrapli/connection.py", line 81, in open
    raise NornirScrapliInvalidPlatform(
nornir_scrapli.exceptions.NornirScrapliInvalidPlatform: 'platform' not provided in inventory for host `192.168.1.11`

2022-07-09 12:13:13,875 - nornir.core.task -    ERROR -      start() - Host 'R3': task 'send_command' failed with traceback:
Traceback (most recent call last):
  File "/home/jcapps/nornir/.venv/lib/python3.10/site-packages/nornir/core/task.py", line 99, in start
    r = self.task(self, **self.params)
  File "/home/jcapps/nornir/.venv/lib/python3.10/site-packages/nornir_scrapli/tasks/core/send_command.py", line 36, in send_command
    scrapli_conn = task.host.get_connection("scrapli", task.nornir.config)
  File "/home/jcapps/nornir/.venv/lib/python3.10/site-packages/nornir/core/inventory.py", line 494, in get_connection
    self.open_connection(
  File "/home/jcapps/nornir/.venv/lib/python3.10/site-packages/nornir/core/inventory.py", line 546, in open_connection
    conn_obj.open(
  File "/home/jcapps/nornir/.venv/lib/python3.10/site-packages/nornir_scrapli/connection.py", line 81, in open
    raise NornirScrapliInvalidPlatform(
nornir_scrapli.exceptions.NornirScrapliInvalidPlatform: 'platform' not provided in inventory for host `192.168.1.13`

2022-07-09 12:13:13,876 - nornir.core.task -    ERROR -      start() - Host 'R2': task 'send_command' failed with traceback:
Traceback (most recent call last):
  File "/home/jcapps/nornir/.venv/lib/python3.10/site-packages/nornir/core/task.py", line 99, in start
    r = self.task(self, **self.params)
  File "/home/jcapps/nornir/.venv/lib/python3.10/site-packages/nornir_scrapli/tasks/core/send_command.py", line 36, in send_command
    scrapli_conn = task.host.get_connection("scrapli", task.nornir.config)
  File "/home/jcapps/nornir/.venv/lib/python3.10/site-packages/nornir/core/inventory.py", line 494, in get_connection
    self.open_connection(
  File "/home/jcapps/nornir/.venv/lib/python3.10/site-packages/nornir/core/inventory.py", line 546, in open_connection
    conn_obj.open(
  File "/home/jcapps/nornir/.venv/lib/python3.10/site-packages/nornir_scrapli/connection.py", line 81, in open
    raise NornirScrapliInvalidPlatform(
nornir_scrapli.exceptions.NornirScrapliInvalidPlatform: 'platform' not provided in inventory for host `192.168.1.12`

2022-07-09 12:13:32,105 -  nornir.core -     INFO -        run() - Running task 'send_command' with args {'command': 'show version'} on 4 hosts
